Workbook

Sheet How to use
A1: How to use this workbook
A2: Generated 2026-09-12 from the MBA 8660 Decision Tools application.
A4: One sheet per week
A5: Each week sheet has three blocks. Inputs you supply, the rates and constants the arithmetic leans on, and the computed figures. Every computed cell holds a formula, and column D says what that formula means in words.
A7: Change an input, not a result
A8: Type over any cell in the Inputs block and the sheet recalculates. If you overwrite a computed cell you have replaced the model with a number, which is the one thing the assignment asks you not to do.
A10: Prices live on the Rates sheet
A11: Published list prices are held once, on the Rates sheet, and every week that uses a price refers to it there. Change a price on that sheet and each week that depends on it follows. Each price carries the vendor, the unit, the date it was retrieved, and its source.
A13: This workbook computes. It does not recommend.
A14: The figures here are arithmetic over assumptions you supplied. They do not choose an architecture, an operating model, or a compliance path, and no amount of recalculating will make them do so. The judgments each week refuses to make are listed in the application, and you are expected to answer them in writing.
A16: Every figure is reproducible
A17: The application shows the same equations beside the week picker, with the cell each one occupies here. If a number in the application and a number in this workbook ever disagree, that is a defect. The test suite checks all twelve weeks against each other on every commit.

Sheet Week 1
A1: Week 1: Working Set Sizing and Cost
A2: Does this workload need a distributed system? Recommend yes or no, and show the sizing arithmetic and the dollar figures that support your answer.
A4: INPUTS YOU SUPPLY | E4: Change any figure in column B. Every computed cell below recalculates.
A5: Item | B5: Value | C5: Unit | D5: Where it comes from
A6: Row count | B6: 4200000000 | C6: rows | D6: The largest single table you must query.
A7: Bytes per row | B7: 310 | C7: bytes | D7: Uncompressed average across every column.
A8: Compression ratio | B8: 4 | C8: x | D8: How many times smaller the data gets on disk. Yours is a measurement, not a constant.
A9: Fraction scanned per query | B9: 0.08 | C9: 0.01 to 1 | D9: What a typical query touches after partition pruning.
A10: Annual growth | B10: 22 | C10: percent | D10: Compounded over three years.
A11: Peak concurrent queries | B11: 14 | C11: queries | D11: Simultaneous queries at the busiest moment.
A12: Queries per day | B12: 900 | C12: queries | D12: Total daily query volume.
A13: Compute hours per day | B13: 12 | C13: hours | D13: Hours the engine is actually running.
A15: RATES AND CONSTANTS | E15: Published list prices link to the Rates sheet. Change a price there and every week that uses it follows.
A16: Item | B16: Value | C16: Unit | D16: Source and note
A17: Bytes per GiB | B17: 1073741824 | C17: bytes | D17: 1,024 cubed. Not one billion, which is where a seven percent error comes from.
A18: GB per GiB | B18: 1.0737418 | C18: GB | D18: Memory is sized in GiB and storage is billed in GB. Convert before pricing anything.
A19: Single-node memory ceiling | B19: 512 | C19: GiB | D19: RAM in the largest single machine this model assumes you can rent.
A20: Memory per cluster worker | B20: 128 | C20: GiB | D20: RAM in one worker of the distributed cluster.
A21: Days per month | B21: 30.42 | C21: days | D21: Average month, used to turn a daily figure into a monthly bill.
A22: Days per year | B22: 365 | C22: days
A23: Months per year | B23: 12 | C23: months
A24: GB per TB | B24: 1000 | C24: GB | D24: Scan pricing is per decimal TB.
A25: Minimum workers in a cluster | B25: 2 | C25: nodes | D25: One worker is not a distributed system.
A26: Cross-zone transfer directions billed | B26: 2 | C26: directions | D26: A byte sent between zones is billed leaving and arriving.
A27: Object storage price | B27: =Rates!$C$5 -> 0.023 | C27: per GB-month | D27: Amazon Web Services, S3 Standard, first 50 TB per month, us-east-1. List price retrieved 2026-08-15. The default landing tier for a lakehouse. Billed on average bytes stored across the month, not peak.
A28: Scan price | B28: =Rates!$C$14 -> 5 | C28: per TB scanned | D28: Amazon Web Services, Athena, SQL over data in S3. List price retrieved 2026-08-15. You pay for bytes the engine reads, not rows returned. Compression and partitioning cut this bill directly.
A29: Single-node compute price | B29: =Rates!$C$12 -> 4.032 | C29: per node-hour | D29: Amazon Web Services, EC2 r5.16xlarge on-demand, 64 vCPU and 512 GiB RAM, us-east-1, Linux. List price retrieved 2026-08-15. The single-node ceiling used throughout Week 1. 512 GiB of RAM in one machine, one address space, no network hop.
A30: Worker node compute price | B30: =Rates!$C$13 -> 1.008 | C30: per node-hour | D30: Amazon Web Services, EC2 r5.4xlarge on-demand, 16 vCPU and 128 GiB RAM, us-east-1, Linux. List price retrieved 2026-08-15. One worker in a distributed cluster. Exactly one quarter the RAM and one quarter the price of the single node above.
A31: Cross-zone transfer price | B31: =Rates!$C$21 -> 0.01 | C31: per GB | D31: Amazon Web Services, Data transfer between availability zones, each direction. List price retrieved 2026-08-15. The hidden tax on a distributed shuffle. Every byte a worker sends to another worker across a zone is billed twice.
A33: COMPUTED | E33: Each cell holds the formula shown in column D. Nothing here is typed in by hand.
A34: Figure | B34: Value | C34: Unit | D34: Equation in words | E34: Note
A35: Raw uncompressed size | B35: =$B$6*$B$7/$B$17 -> 1212.582 | C35: GiB | D35: Row count × Bytes per row ÷ Bytes per GiB | E35: Rows times bytes per row. The number nobody ever actually stores.
A36: Columnar estimate | B36: =$B$35/$B$8 -> 303.1455 | C36: GiB | D36: Raw uncompressed size ÷ Compression ratio | E36: What the bytes occupy once written as compressed columnar files.
A37: Bytes removed by compression | B37: =$B$35-$B$36 -> 909.43649 | C37: GiB | D37: Raw uncompressed size - Columnar estimate | E37: Storage you do not rent and bytes you do not scan. Billed twice over.
A38: Working set per query | B38: =$B$36*$B$9 -> 24.25164 | C38: GiB | D38: Columnar estimate × Fraction scanned per query | E38: This, not table size, is what has to fit in memory.
A39: Working set at peak concurrency | B39: =$B$38*$B$11 -> 339.52296 | C39: GiB | D39: Working set per query × Peak concurrent queries | E39: Every simultaneous query holds its own working set.
A40: Working set in year three | B40: =$B$39*(1+$B$10/100)^3 -> 616.52208 | C40: GiB | D40: Working set at peak concurrency × (1 + Annual growth ÷ 100) ^ 3 | E40: Architecture is chosen for this figure, not today's.
A41: Headroom against the single node | B41: =$B$19/$B$40 -> 0.83046498 | C41: x | D41: Single-node memory ceiling ÷ Working set in year three | E41: Above 1.0 the workload still fits on one machine in year three.
A42: Storage, compressed, per month | B42: =$B$36*$B$18*$B$27 -> 7.4865 | C42: USD per month | D42: Columnar estimate × GB per GiB × Object storage price
A43: Storage, uncompressed, per month | B43: =$B$35*$B$18*$B$27 -> 29.946 | C43: USD per month | D43: Raw uncompressed size × GB per GiB × Object storage price | E43: What the same data would cost stored raw.
...

Sheet Week 2
A1: Week 2: Table Format Lock-In and Exit Cost
A2: Recommend a table format. Name the vendor lock-in you are accepting, say why you accept it, and price the exit.
A4: INPUTS YOU SUPPLY | E4: Change any figure in column B. Every computed cell below recalculates.
A5: Item | B5: Value | C5: Unit | D5: Where it comes from
A6: Table format | B6: Iceberg | D6: Iceberg, Delta Lake, or Hudi.
A7: Primary engine | B7: Trino | D7: The engine doing most of the reading.
A8: Engines requiring read access | B8: 3 | C8: engines | D8: Portability only matters when more than one engine reads the same table.
A9: Catalog vendor relationship | B9: Independent | D9: Same as engine, or Independent.
A10: Data volume | B10: 1.5 | C10: PB | D10: Total bytes that would have to be rewritten to leave.
A11: Migration leaves the cloud | B11: No | D11: Yes or No. Egress is charged only when the bytes leave.
A13: RATES AND CONSTANTS | E13: Published list prices link to the Rates sheet. Change a price there and every week that uses it follows.
A14: Item | B14: Value | C14: Unit | D14: Source and note
A15: Rewrite throughput assumed | B15: 5 | C15: TB per hour | D15: A sustained rate for a well-provisioned rewrite job. Your measured rate may differ by an order of magnitude.
A16: Workers held for the rewrite | B16: 20 | C16: nodes
A17: TB per PB | B17: 1000 | C17: TB
A18: GB per TB | B18: 1000 | C18: GB
A19: Hours per day | B19: 24 | C19: hours
A20: Rewrite compute price | B20: =Rates!$C$13 -> 1.008 | C20: per node-hour | D20: Amazon Web Services, EC2 r5.4xlarge on-demand, 16 vCPU and 128 GiB RAM, us-east-1, Linux. List price retrieved 2026-08-15. One worker in a distributed cluster. Exactly one quarter the RAM and one quarter the price of the single node above.
A21: Egress price | B21: =Rates!$C$20 -> 0.09 | C21: per GB | D21: Amazon Web Services, Data transfer out to the internet, beyond the first 100 GB per month. List price retrieved 2026-08-15. Roughly 4x the monthly cost of storing the same byte. Egress is what makes leaving a cloud expensive.
A23: COMPUTED | E23: Each cell holds the formula shown in column D. Nothing here is typed in by hand.
A24: Figure | B24: Value | C24: Unit | D24: Equation in words | E24: Note
A25: Full-rewrite time | B25: =$B$10*$B$17/$B$15 -> 300 | C25: hours | D25: Data volume × TB per PB ÷ Rewrite throughput assumed | E25: Mechanical time to rewrite every byte, assuming nothing goes wrong.
A26: Full-rewrite time in days | B26: =$B$25/$B$19 -> 12.5 | C26: days | D26: Full-rewrite time ÷ Hours per day | E26: The same figure in a unit an executive will actually hear.
A27: Rewrite compute cost | B27: =$B$25*$B$20*$B$16 -> 6048 | C27: USD | D27: Full-rewrite time × Rewrite compute price × Workers held for the rewrite
A28: Egress cost to leave the cloud | B28: =IF($B$11="Yes",$B$10*$B$17*$B$18*$B$21,0) -> 0 | C28: USD | D28: IF(Migration leaves the cloud="Yes",Data volume × TB per PB × GB per TB × Egress price,0) | E28: Zero when the migration stays inside one cloud.
A29: Mechanical cost of leaving | B29: =$B$27+$B$28 -> 6048 | C29: USD | D29: Rewrite compute cost + Egress cost to leave the cloud | E29: Excludes every hour of human time, which is the larger number.

Sheet Week 3
A1: Week 3: Catalog Failure Modes and Cost
A2: Choose a catalog. Name the failure mode you inherit with that choice, say how you would detect it, and price the catalog itself.
A4: INPUTS YOU SUPPLY | E4: Change any figure in column B. Every computed cell below recalculates.
A5: Item | B5: Value | C5: Unit | D5: Where it comes from
A6: Catalog hosting | B6: Managed by vendor | D6: Managed by vendor, or Self-hosted.
A7: Credential handling | B7: Vended by catalog | D7: Vended by catalog, or Direct storage credentials.
A8: Autonomous agent access | B8: Permitted | D8: Permitted, or Not permitted.
A9: Recovery time objective | B9: 60 | C9: minutes | D9: How long you have agreed the catalog may stay down.
A10: Tables under management | B10: 900 | C10: tables | D10: Every table is one catalog object.
A11: Partitions per table | B11: 1095 | C11: partitions | D11: Three years of daily partitions is about 1,095.
A12: Queries per day | B12: 20000 | C12: queries | D12: Catalog requests scale with query count, not data volume.
A14: RATES AND CONSTANTS | E14: Published list prices link to the Rates sheet. Change a price there and every week that uses it follows.
A15: Item | B15: Value | C15: Unit | D15: Source and note
A16: Catalog lookups per query | B16: 4 | C16: lookups | D16: Planning hits the catalog several times before reading a byte.
A17: Days per month | B17: 30.42 | C17: days
A18: Catalog objects included free | B18: 1000000 | C18: objects
A19: Objects per priced block | B19: 100000 | C19: objects
A20: Catalog requests included free | B20: 1000000 | C20: requests
A21: Requests per priced block | B21: 1000000 | C21: requests
A22: Nodes for a self-hosted quorum | B22: 3 | C22: nodes
A23: Hours per month | B23: 730 | C23: hours | D23: The figure cloud vendors bill against.
A24: Hours per year | B24: 8760 | C24: hours | D24: Used for the hourly audit log.
A25: Failure modes before agent access | B25: 2 | C25: modes | D25: One for hosting, one for credential handling.
A26: Catalog object price | B26: =Rates!$C$22 -> 1 | C26: per 100,000 objects per month | D26: Amazon Web Services, AWS Glue Data Catalog storage, beyond the first 1,000,000 objects. List price retrieved 2026-08-15. An object is a table, partition, or database. Partition count, not table count, is what usually blows past the free tier.
A27: Catalog request price | B27: =Rates!$C$23 -> 1 | C27: per 1,000,000 requests | D27: Amazon Web Services, AWS Glue Data Catalog requests, beyond the first 1,000,000 per month. List price retrieved 2026-08-15. Every query plan hits the catalog several times. Catalog requests scale with query count, not data volume.
A28: Self-hosting compute price | B28: =Rates!$C$13 -> 1.008 | C28: per node-hour | D28: Amazon Web Services, EC2 r5.4xlarge on-demand, 16 vCPU and 128 GiB RAM, us-east-1, Linux. List price retrieved 2026-08-15. One worker in a distributed cluster. Exactly one quarter the RAM and one quarter the price of the single node above.
A30: COMPUTED | E30: Each cell holds the formula shown in column D. Nothing here is typed in by hand.
A31: Figure | B31: Value | C31: Unit | D31: Equation in words | E31: Note
A32: Failure modes surfaced | B32: =$B$25+IF($B$8="Permitted",1,0) -> 3 | C32: modes | D32: Failure modes before agent access + IF(Autonomous agent access="Permitted",1,0) | E32: Hosting and credential handling each contribute one. Agent access adds a third.
A33: Catalog objects | B33: =$B$10*(1+$B$11) -> 986400 | C33: objects | D33: Tables under management × (1 + Partitions per table) | E33: Tables plus partitions. Partition count is what crosses the free tier.
A34: Catalog storage per month | B34: =MAX(0,$B$33-$B$18)/$B$19*$B$26 -> 0 | C34: USD per month | D34: MAX(0,Catalog objects - Catalog objects included free) ÷ Objects per priced block × Catalog object price
A35: Catalog requests per month | B35: =$B$12*$B$16*$B$17 -> 2433600 | C35: requests | D35: Queries per day × Catalog lookups per query × Days per month | E35: The line after this one prices them; this one counts them.
A36: Catalog request cost per month | B36: =MAX(0,$B$35-$B$20)/$B$21*$B$27 -> 1.4336 | C36: USD per month | D36: MAX(0,Catalog requests per month - Catalog requests included free) ÷ Requests per priced block × Catalog request price
A37: Self-hosting compute per month | B37: =IF($B$6="Self-hosted",$B$28*$B$22*$B$23,0) -> 0 | C37: USD per month | D37: IF(Catalog hosting="Self-hosted",Self-hosting compute price × Nodes for a self-hosted quorum × Hours per month,0) | E37: Zero when the vendor hosts it.
A38: Catalog cost per month | B38: =$B$34+$B$36+$B$37 -> 1.4336 | C38: USD per month | D38: Catalog storage per month + Catalog request cost per month + Self-hosting compute per month | E38: Small in absolute terms. That is the point.
A39: Audit rows per year at hourly granularity | B39: =$B$10*$B$24 -> 7884000 | C39: rows | D39: Tables under management × Hours per year | E39: One access-log row per table per hour. Retaining this log is itself a storage decision.

Sheet Week 4
A1: Week 4: Engine Cost Against Budget Ceiling
A2: Recommend an engine under a fixed annual budget. State explicitly what capability you gave up to stay inside it.
A4: INPUTS YOU SUPPLY | E4: Change any figure in column B. Every computed cell below recalculates.
A5: Item | B5: Value | C5: Unit | D5: Where it comes from
A6: Annual budget ceiling | B6: 1450000 | C6: USD | D6: The Final Artifact constraint.
A7: Published unit price | B7: 2 | C7: USD | D7: From the vendor pricing page, not from memory.
A8: Price unit | B8: per credit | D8: Per credit, per TB scanned, per DBU, or per node hour.
A9: Price retrieved on | B9: 46249 | C9: date | D9: An undated price is not evidence.
A10: Expected units per month | B10: 12000 | C10: units | D10: A forecast you supplied, and the largest source of error here.
A11: Committed-use discount | B11: 20 | C11: percent | D11: A multi-year obligation traded for a lower rate.
A12: Storage under management | B12: 400 | C12: TB | D12: A compute-only budget is not a platform budget.
A14: RATES AND CONSTANTS | E14: Published list prices link to the Rates sheet. Change a price there and every week that uses it follows.
A15: Item | B15: Value | C15: Unit | D15: Source and note
A16: Months per year | B16: 12 | C16: months
A17: GB per TB | B17: 1000 | C17: GB | D17: Storage is priced per GB-month.
A18: Object storage price | B18: =Rates!$C$5 -> 0.023 | C18: per GB-month | D18: Amazon Web Services, S3 Standard, first 50 TB per month, us-east-1. List price retrieved 2026-08-15. The default landing tier for a lakehouse. Billed on average bytes stored across the month, not peak.
A20: COMPUTED | E20: Each cell holds the formula shown in column D. Nothing here is typed in by hand.
A21: Figure | B21: Value | C21: Unit | D21: Equation in words | E21: Note
A22: Compute at list price | B22: =$B$7*$B$10*$B$16 -> 288000 | C22: USD per year | D22: Published unit price × Expected units per month × Months per year | E22: Nobody is quoted a discount before they ask.
A23: Compute after commit discount | B23: =$B$22*(1-$B$11/100) -> 230400 | C23: USD per year | D23: Compute at list price × (1 - Committed-use discount ÷ 100) | E23: What you pay if the forecast holds. If it does not, you still owe the commitment.
A24: Storage per year | B24: =$B$12*$B$17*$B$18*$B$16 -> 110400 | C24: USD per year | D24: Storage under management × GB per TB × Object storage price × Months per year
A25: Platform total per year | B25: =$B$23+$B$24 -> 340800 | C25: USD per year | D25: Compute after commit discount + Storage per year | E25: This, not the compute line, is what the ceiling has to cover.
A26: Budget remaining | B26: =$B$6-$B$25 -> 1109200 | C26: USD per year | D26: Annual budget ceiling - Platform total per year | E26: Your entire margin for a forecast error or a price rise.
A27: Ceiling utilisation | B27: =$B$25/$B$6*100 -> 23.503448 | C27: percent | D27: Platform total per year ÷ Annual budget ceiling × 100 | E27: Above 85 percent there is no room inside the budget year.
A28: Units per month that exhaust the ceiling | B28: =($B$6-$B$24)/(1-$B$11/100)/$B$7/$B$16 -> 69770.833 | C28: units per month | D28: (Annual budget ceiling - Storage per year) ÷ (1 - Committed-use discount ÷ 100) ÷ Published unit price ÷ Months per year | E28: The volume at which compute plus storage exactly equals the ceiling.

Sheet Week 5
A1: Week 5: Spend Reduction and Unit Economics
A2: Cut 20 percent of platform spend. Name what breaks, who complains, what you tell them, and what the cut does to cost per query.
A4: INPUTS YOU SUPPLY | E4: Change any figure in column B. Every computed cell below recalculates.
A5: Item | B5: Value | C5: Unit | D5: Where it comes from
A6: Target reduction | B6: 20 | C6: percent | D6: The mandate you were handed.
A7: Queries per year | B7: 4000000 | C7: queries | D7: The denominator for cost per query.
A8: Monthly active users | B8: 850 | C8: people | D8: The denominator for cost per user.
A9: Storage annual spend | B9: 300000 | C9: USD | D9: Current annual storage spend, from the invoice rather than the budget.
A10: Compute annual spend | B10: 900000 | C10: USD | D10: Current annual compute spend, from the invoice rather than the budget.
A11: Ingestion annual spend | B11: 200000 | C11: USD | D11: Current annual ingestion spend, from the invoice rather than the budget.
A12: Observability annual spend | B12: 150000 | C12: USD | D12: Current annual observability spend, from the invoice rather than the budget.
A13: Licences annual spend | B13: 250000 | C13: USD | D13: Current annual licences spend, from the invoice rather than the budget.
A14: Storage cut | B14: 10 | C14: percent | D14: Share of storage you propose to remove.
A15: Compute cut | B15: 25 | C15: percent | D15: Share of compute you propose to remove.
A16: Ingestion cut | B16: 15 | C16: percent | D16: Share of ingestion you propose to remove.
A17: Observability cut | B17: 5 | C17: percent | D17: Share of observability you propose to remove.
A18: Licences cut | B18: 30 | C18: percent | D18: Share of licences you propose to remove.
A20: RATES AND CONSTANTS | E20: Published list prices link to the Rates sheet. Change a price there and every week that uses it follows.
A21: Item | B21: Value | C21: Unit | D21: Source and note
A23: COMPUTED | E23: Each cell holds the formula shown in column D. Nothing here is typed in by hand.
A24: Figure | B24: Value | C24: Unit | D24: Equation in words | E24: Note
A25: Total annual platform spend | B25: =$B$9+$B$10+$B$11+$B$12+$B$13 -> 1800000 | C25: USD per year | D25: Storage annual spend + Compute annual spend + Ingestion annual spend + Observability annual spend + Licences annual spend | E25: Every category added up. The number nobody can act on.
A26: Storage saving | B26: =$B$9*$B$14/100 -> 30000 | C26: USD per year | D26: Storage annual spend × Storage cut ÷ 100 | E26: Spend times cut percentage. Compare this against how much the storage cut hurts.
A27: Compute saving | B27: =$B$10*$B$15/100 -> 225000 | C27: USD per year | D27: Compute annual spend × Compute cut ÷ 100 | E27: Spend times cut percentage. Compare this against how much the compute cut hurts.
A28: Ingestion saving | B28: =$B$11*$B$16/100 -> 30000 | C28: USD per year | D28: Ingestion annual spend × Ingestion cut ÷ 100 | E28: Spend times cut percentage. Compare this against how much the ingestion cut hurts.
A29: Observability saving | B29: =$B$12*$B$17/100 -> 7500 | C29: USD per year | D29: Observability annual spend × Observability cut ÷ 100 | E29: Spend times cut percentage. Compare this against how much the observability cut hurts.
A30: Licences saving | B30: =$B$13*$B$18/100 -> 75000 | C30: USD per year | D30: Licences annual spend × Licences cut ÷ 100 | E30: Spend times cut percentage. Compare this against how much the licences cut hurts.
A31: Total saving | B31: =$B$26+$B$27+$B$28+$B$29+$B$30 -> 367500 | C31: USD per year | D31: Storage saving + Compute saving + Ingestion saving + Observability saving + Licences saving | E31: What this plan actually removes from next year's bill.
A32: Spend after the cuts | B32: =$B$25-$B$31 -> 1432500 | C32: USD per year | D32: Total annual platform spend - Total saving | E32: The figure both unit-economics lines below are computed from.
A33: Reduction achieved | B33: =$B$31/$B$25*100 -> 20.416667 | C33: percent | D33: Total saving ÷ Total annual platform spend × 100 | E33: Total saving as a share of total spend.
A34: Gap to target | B34: =IF($B$6/100*$B$25-$B$31>0,$B$6/100*$B$25-$B$31,"Target met") -> Target met | C34: USD per year | D34: IF(Target reduction ÷ 100 × Total annual platform spend - Total saving>0,Target reduction ÷ 100 × Total annual platform spend - Total saving,"Target met") | E34: What is still missing. A plan that is short is not a plan, it is a direction.
A35: Cost per query, before | B35: =$B$25/$B$7 -> 0.45 | C35: USD | D35: Total annual platform spend ÷ Queries per year | E35: This is the FinOps unit, not the total.
A36: Cost per query, after | B36: =$B$32/$B$7 -> 0.358125 | C36: USD | D36: Spend after the cuts ÷ Queries per year
A37: Cost per active user per year, before | B37: =$B$25/$B$8 -> 2117.6471 | C37: USD | D37: Total annual platform spend ÷ Monthly active users | E37: Denominates the platform in people rather than infrastructure.
A38: Cost per active user per year, after | B38: =$B$32/$B$8 -> 1685.2941 | C38: USD | D38: Spend after the cuts ÷ Monthly active users

Sheet Week 6
A1: Week 6: Build Versus Buy Break-Even
A2: Build or buy. Show the break-even in months and name the single assumption the answer hinges on.
A4: INPUTS YOU SUPPLY | E4: Change any figure in column B. Every computed cell below recalculates.
A5: Item | B5: Value | C5: Unit | D5: Where it comes from
A6: Vendor monthly price | B6: 9000 | C6: USD per month | D6: The quoted price, dated.
A7: Price retrieved on | B7: 46249 | C7: date | D7: An undated price is not evidence.
A8: One-time build effort | B8: 900 | C8: hours | D8: Engineering to first production use.
A9: Blended hourly cost | B9: 140 | C9: USD per hour | D9: Fully loaded, not salary divided by 2,080.
A10: Maintenance effort | B10: 30 | C10: hours per month | D10: The figure teams underestimate most.
A11: Infrastructure for the build | B11: 1200 | C11: USD per month | D11: A vendor price already includes theirs.
A12: Evaluation horizon | B12: 36 | C12: months | D12: It frequently decides the answer by itself.
A14: RATES AND CONSTANTS | E14: Published list prices link to the Rates sheet. Change a price there and every week that uses it follows.
A15: Item | B15: Value | C15: Unit | D15: Source and note
A17: COMPUTED | E17: Each cell holds the formula shown in column D. Nothing here is typed in by hand.
A18: Figure | B18: Value | C18: Unit | D18: Equation in words | E18: Note
A19: One-time build cost | B19: =$B$8*$B$9 -> 126000 | C19: USD | D19: One-time build effort × Blended hourly cost | E19: Paid once, before any value arrives.
A20: Build running cost per month | B20: =$B$10*$B$9+$B$11 -> 5400 | C20: USD per month | D20: Maintenance effort × Blended hourly cost + Infrastructure for the build | E20: Maintenance labour plus infrastructure. This recurs forever, unlike the build.
A21: Monthly saving from building | B21: =$B$6-$B$20 -> 3600 | C21: USD per month | D21: Vendor monthly price - Build running cost per month | E21: If this is not positive, building never repays and the application prints None.
A22: Break-even | B22: =IF($B$21>0,$B$19/$B$21,"Never") -> 35 | C22: months | D22: IF(Monthly saving from building>0,One-time build cost ÷ Monthly saving from building,"Never") | E22: The month cumulative build cost equals cumulative vendor cost.
A23: Maintenance over the horizon | B23: =$B$10*$B$9*$B$12 -> 151200 | C23: USD | D23: Maintenance effort × Blended hourly cost × Evaluation horizon | E23: Charted in the application as part of what the build costs.
A24: Infrastructure over the horizon | B24: =$B$11*$B$12 -> 43200 | C24: USD | D24: Infrastructure for the build × Evaluation horizon | E24: Charted in the application as part of what the build costs.
A25: Build total over the horizon | B25: =$B$19+$B$20*$B$12 -> 320400 | C25: USD | D25: One-time build cost + Build running cost per month × Evaluation horizon
A26: Vendor total over the horizon | B26: =$B$6*$B$12 -> 324000 | C26: USD | D26: Vendor monthly price × Evaluation horizon | E26: Monthly price times the horizon, assuming the price holds.
A27: Difference over the horizon | B27: =ABS($B$25-$B$26) -> 3600 | C27: USD | D27: ABS(Build total over the horizon - Vendor total over the horizon) | E27: The size of the bet you are making on your own maintenance estimate.

Sheet Week 7
A1: Week 7: Reliability Control Pricing
A2: Which single control would have caught this incident, what does it cost per year, and how much faster would you have known?
A4: INPUTS YOU SUPPLY | E4: Change any figure in column B. Every computed cell below recalculates.
A5: Item | B5: Value | C5: Unit | D5: Where it comes from
A6: Control name | B6: Freshness SLA monitor on the orders table | D6: One control, not a programme.
A7: Annual tooling cost | B7: 48000 | C7: USD per year | D7: Licence or subscription.
A8: Setup effort | B8: 120 | C8: hours | D8: One-time integration, paid in year one only.
A9: Operating effort | B9: 8 | C9: hours per month | D9: Tuning, triage, and acting on what it finds.
A10: Blended hourly cost | B10: 140 | C10: USD per hour | D10: Fully loaded cost of an engineering hour.
A11: Cost of one incident | B11: 400000 | C11: USD | D11: Including the work to recover from it.
A12: Expected incidents per year | B12: 1.5 | C12: incidents | D12: From your own history or the assigned post-mortem.
A13: Share of incidents caught | B13: 60 | C13: percent | D13: What it would actually have caught.
A14: Hours to detect today | B14: 18 | C14: hours | D14: The multiplier on every other cost.
A15: Hours to detect with the control | B15: 1 | C15: hours | D15: What this control changes.
A17: RATES AND CONSTANTS | E17: Published list prices link to the Rates sheet. Change a price there and every week that uses it follows.
A18: Item | B18: Value | C18: Unit | D18: Source and note
A19: Months per year | B19: 12 | C19: months
A21: COMPUTED | E21: Each cell holds the formula shown in column D. Nothing here is typed in by hand.
A22: Figure | B22: Value | C22: Unit | D22: Equation in words | E22: Note
A23: Steady-state annual cost | B23: =$B$7+$B$9*$B$19*$B$10 -> 61440 | C23: USD per year | D23: Annual tooling cost + Operating effort × Months per year × Blended hourly cost | E23: What it costs every year after the first. This is the number to compare against.
A24: Year one cost | B24: =$B$23+$B$8*$B$10 -> 78240 | C24: USD | D24: Steady-state annual cost + Setup effort × Blended hourly cost | E24: Tooling plus setup plus a year of operating effort.
A25: Annual incident exposure | B25: =$B$11*$B$12 -> 600000 | C25: USD per year | D25: Cost of one incident × Expected incidents per year | E25: With no control in place.
A26: Exposure avoided | B26: =$B$25*$B$13/100 -> 360000 | C26: USD per year | D26: Annual incident exposure × Share of incidents caught ÷ 100 | E26: Exposure this control removes, if your catch rate estimate holds.
A27: Net annual position | B27: =$B$26-$B$23 -> 298560 | C27: USD per year | D27: Exposure avoided - Steady-state annual cost | E27: Positive is not the same as fundable.
A28: Incidents caught per year | B28: =$B$12*$B$13/100 -> 0.9 | C28: incidents | D28: Expected incidents per year × Share of incidents caught ÷ 100 | E28: The denominator of the cost per incident caught below.
A29: Cost per incident caught | B29: =IF($B$28=0,0,$B$23/$B$28) -> 68266.667 | C29: USD | D29: IF(Incidents caught per year=0,0,Steady-state annual cost ÷ Incidents caught per year) | E29: The unit economics of reliability.
A30: Detection time factor | B30: =IF($B$14=0,1,$B$15/$B$14) -> 0.055555556 | C30: x | D30: IF(Hours to detect today=0,1,Hours to detect with the control ÷ Hours to detect today) | E30: How much shorter an incident runs once the control exists.
A31: Residual exposure after detection speed-up | B31: =($B$25-$B$26)*$B$30 -> 13333.333 | C31: USD per year | D31: (Annual incident exposure - Exposure avoided) × Detection time factor | E31: Exposure from missed incidents, scaled by the shorter time they now run.

Sheet Week 8
A1: Week 8: Operating Model Weighting and Staffing Cost
A2: Centralize or federate data ownership. Defend the choice against its strongest counterargument, not its weakest.
A4: INPUTS YOU SUPPLY | E4: Change any figure in column B. Every computed cell below recalculates.
A5: Item | B5: Value | C5: Unit | D5: Where it comes from
A6: Speed of change weight | B6: 8 | C6: 0 to 10 | D6: How much this criterion matters to your case organization.
A7: Speed of change, centralized score | B7: 4 | C7: 0 to 10 | D7: Your judgment of how the centralized model performs here.
A8: Speed of change, federated score | B8: 8 | C8: 0 to 10 | D8: Your judgment of how the federated model performs here.
A9: Consistency of definitions weight | B9: 9 | C9: 0 to 10 | D9: How much this criterion matters to your case organization.
A10: Consistency of definitions, centralized score | B10: 9 | C10: 0 to 10 | D10: Your judgment of how the centralized model performs here.
A11: Consistency of definitions, federated score | B11: 4 | C11: 0 to 10 | D11: Your judgment of how the federated model performs here.
A12: Domain expertise weight | B12: 7 | C12: 0 to 10 | D12: How much this criterion matters to your case organization.
A13: Domain expertise, centralized score | B13: 3 | C13: 0 to 10 | D13: Your judgment of how the centralized model performs here.
A14: Domain expertise, federated score | B14: 9 | C14: 0 to 10 | D14: Your judgment of how the federated model performs here.
A15: Audit burden weight | B15: 6 | C15: 0 to 10 | D15: How much this criterion matters to your case organization.
A16: Audit burden, centralized score | B16: 8 | C16: 0 to 10 | D16: Your judgment of how the centralized model performs here.
A17: Audit burden, federated score | B17: 4 | C17: 0 to 10 | D17: Your judgment of how the federated model performs here.
... A24: Cost per engineer | B24: 190000 | C24: USD per year | D24: Salary, payroll tax, benefits, equipment, and overhead.
A26: RATES AND CONSTANTS | E26: Published list prices link to the Rates sheet. Change a price there and every week that uses it follows.
A27: Item | B27: Value | C27: Unit | D27: Source and note
A28: Central team retained under federation | B28: 2 | C28: divisor | D28: The federated model keeps a half-size central enablement team, so headcount is divided by two and rounded up.
A29: Floor on the score margin | B29: 0.01 | C29: points | D29: Prevents a division by zero when the two models score identically.
A31: COMPUTED | E31: Each cell holds the formula shown in column D. Nothing here is typed in by hand.
A32: Figure | B32: Value | C32: Unit | D32: Equation in words | E32: Note
A33: Total weight | B33: =$B$6+$B$9+$B$12+$B$15+$B$18 -> 39 | C33: points | D33: Speed of change weight + Consistency of definitions weight + Domain expertise weight + Audit burden weight + Staffing reality weight | E33: The divisor that turns weighted sums into a score out of ten.
A34: Centralized weighted sum | B34: =$B$6*$B$7+$B$9*$B$10+$B$12*$B$13+$B$15*$B$16+$B$18*$B$19 -> 245 | C34: points | D34: Speed of change weight × Speed of change, centralized score + Consistency of definitions weight × Consistency of definitions, centralized score + Domain expertise weight × Domain expertise, centralized score + Audit burden weight × Audit burden, centralized score + Staffing reality weight × Staffing reality, centralized score | E34: Each centralized score times its weight.
A35: Federated weighted sum | B35: =$B$6*$B$8+$B$9*$B$11+$B$12*$B$14+$B$15*$B$17+$B$18*$B$20 -> 214 | C35: points | D35: Speed of change weight × Speed of change, federated score + Consistency of definitions weight × Consistency of definitions, federated score + Domain expertise weight × Domain expertise, federated score + Audit burden weight × Audit burden, federated score + Staffing reality weight × Staffing reality, federated score | E35: Each federated score times its weight.
A36: Weighted centralized score | B36: =$B$34/$B$33 -> 6.2820513 | C36: of 10 | D36: Centralized weighted sum ÷ Total weight
A37: Weighted federated score | B37: =$B$35/$B$33 -> 5.4871795 | C37: of 10 | D37: Federated weighted sum ÷ Total weight
A38: Margin | B38: =ABS($B$36-$B$37) -> 0.79487179 | C38: points | D38: ABS(Weighted centralized score - Weighted federated score) | E38: Under half a point, the weights are deciding rather than the evidence.
A39: Centralized staffing cost per year | B39: =$B$21*$B$24 -> 1520000 | C39: USD per year | D39: Central platform headcount × Cost per engineer
A40: Federated staffing cost per year | B40: =($B$23*$B$22+CEILING($B$21/$B$28,1))*$B$24 -> 3040000 | C40: USD per year | D40: (Business domains × Engineers per domain + CEILING(Central platform headcount ÷ Central team retained under federation,1)) × Cost per engineer | E40: Domains times engineers each, plus a half-size central enablement team.
A41: Annual staffing difference | B41: =ABS($B$40-$B$39) -> 1520000 | C41: USD per year | D41: ABS(Federated staffing cost per year - Centralized staffing cost per year) | E41: Operating models are mostly a payroll decision. This is the size of it.
A42: Cost per point of weighted score | B42: =$B$41/MAX($B$38,$B$29) -> 1912258.1 | C42: USD per point | D42: Annual staffing difference ÷ MAX(Margin,Floor on the score margin) | E42: What the dearer model costs per point of advantage your own weights gave it.

Sheet Week 9
A1: Week 9: Privacy Compliance Path Cost
A2: Adopt one national internal standard or comply state by state. Cost both paths and pick one.
A4: INPUTS YOU SUPPLY | E4: Change any figure in column B. Every computed cell below recalculates.
A5: Item | B5: Value | C5: Unit | D5: Where it comes from
A6: States in scope | B6: 19 | C6: states | D6: States whose statutes reach your data subjects.
A7: Strictest state driving the standard | B7: California | D7: The state whose rule sets your national floor.
A8: National standard build | B8: 750000 | C8: USD | D8: One-time cost to build to the strictest standard.
A9: National standard annual | B9: 200000 | C9: USD per year | D9: One jurisdiction's worth of process applied to all of them.
A10: Per-state build | B10: 60000 | C10: USD | D10: One-time cost per state.
A11: Per-state annual | B11: 25000 | C11: USD per year | D11: The line that compounds.
A12: Horizon | B12: 3 | C12: years | D12: Longer horizons favour the one-time build.
A13: Deletion requests per year | B13: 4200 | C13: requests | D13: Statutory deletion and access requests you expect to service.
A14: Hours per request | B14: 1.5 | C14: hours | D14: Manual effort per request today.
A16: RATES AND CONSTANTS | E16: Published list prices link to the Rates sheet. Change a price there and every week that uses it follows.
A17: Item | B17: Value | C17: Unit | D17: Source and note
A18: Blended hourly cost | B18: 140 | C18: USD per hour | D18: An organizational assumption, not a published price. Salary divided by 2,080 understates it badly.
A20: COMPUTED | E20: Each cell holds the formula shown in column D. Nothing here is typed in by hand.
A21: Figure | B21: Value | C21: Unit | D21: Equation in words | E21: Note
A22: National standard over the horizon | B22: =$B$8+$B$9*$B$12 -> 1350000 | C22: USD | D22: National standard build + National standard annual × Horizon | E22: Build once to the strictest rule, run it everywhere.
A23: Per-state compliance over the horizon | B23: =$B$10*$B$6+$B$11*$B$6*$B$12 -> 2565000 | C23: USD | D23: Per-state build × States in scope + Per-state annual × States in scope × Horizon | E23: Separate builds and separate annual programmes, one set per state.
A24: Difference | B24: =ABS($B$23-$B$22) -> 1215000 | C24: USD | D24: ABS(Per-state compliance over the horizon - National standard over the horizon) | E24: The size of the decision, over the horizon you stated.
A25: States at which the two paths cost the same | B25: =($B$8+$B$9*$B$12)/($B$10+$B$11*$B$12) -> 10 | C25: states | D25: (National standard build + National standard annual × Horizon) ÷ (Per-state build + Per-state annual × Horizon) | E25: Below this count, per-state is cheaper. Above it, the national standard is.
A26: Deletion request handling per year | B26: =$B$13*$B$14*$B$18 -> 882000 | C26: USD per year | D26: Deletion requests per year × Hours per request × Blended hourly cost | E26: Recurs on both paths and grows with your customer base.
A27: Cost per deletion request | B27: =$B$26/$B$13 -> 210 | C27: USD | D27: Deletion request handling per year ÷ Deletion requests per year | E27: Automation is justified against this figure, not against the total.
A28: National standard, per state per year | B28: =$B$22/$B$12/$B$6 -> 23684.211 | C28: USD | D28: National standard over the horizon ÷ Horizon ÷ States in scope | E28: Compare it against the per-state annual figure you entered.

Sheet Week 10
A1: Week 10: EU AI Act Exposure Timeline
A2: Article 50 transparency duties apply now. High-risk duties were deferred. Does your roadmap change, and by how much?
A4: INPUTS YOU SUPPLY | E4: Change any figure in column B. Every computed cell below recalculates.
A5: Item | B5: Value | C5: Unit | D5: Where it comes from
A6: Assessed as of | B6: 46277 | C6: date | D6: Every day count is measured from this date. The application uses the day you run it.
A7: Your role under the Act | B7: Deployer | D7: Provider, Deployer, Both, or Neither.
A8: Annex III use case in scope | B8: Unsure | D8: Yes, No, or Unsure. Unsure is a finding, not a gap.
A9: Uses a general-purpose AI model | B9: Yes | D9: Yes or No.
A10: Generates synthetic content | B10: Yes | D10: Yes or No. Triggers Article 50 duties, already in force.
A11: Readiness effort | B11: 900 | C11: hours | D11: Your estimate of the work to reach compliance.
A12: Blended hourly cost | B12: 140 | C12: USD per hour | D12: Fully loaded cost of an engineering or compliance hour.
A14: RATES AND CONSTANTS | E14: Published list prices link to the Rates sheet. Change a price there and every week that uses it follows.
A15: Item | B15: Value | C15: Unit | D15: Source and note
A16: 2025-02-02 | B16: 45690 | C16: date | D16: Prohibitions and AI literacy obligations apply
A17: 2025-08-02 | B17: 45871 | C17: date | D17: GPAI model provider obligations and governance apply
A18: 2026-08-02 | B18: 46236 | C18: date | D18: Article 50 transparency duties apply, and AI Office enforcement over GPAI begins
A19: 2026-12-02 | B19: 46358 | C19: date | D19: Deadline for transparency solutions for artificially generated content
A20: 2027-08-02 | B20: 46601 | C20: date | D20: Member State AI regulatory sandboxes operational
A21: 2027-12-02 | B21: 46723 | C21: date | D21: Annex III standalone high-risk obligations apply, deferred by the Digital Omnibus
A22: 2028-08-02 | B22: 46967 | C22: date | D22: Annex I product-embedded high-risk obligations apply, deferred by the Digital Omnibus
A23: Days per week | B23: 7 | C23: days
A25: COMPUTED | E25: Each cell holds the formula shown in column D. Nothing here is typed in by hand.
A26: Figure | B26: Value | C26: Unit | D26: Equation in words | E26: Note
A27: Days to 2025-02-02 | B27: =ROUND($B$16-$B$6,0) -> -587 | C27: days | D27: ROUND(2025-02-02 - Assessed as of,0) | E27: Prohibitions and AI literacy obligations apply A negative figure means the obligation is already in force.
A28: Days to 2025-08-02 | B28: =ROUND($B$17-$B$6,0) -> -406 | C28: days | D28: ROUND(2025-08-02 - Assessed as of,0) | E28: GPAI model provider obligations and governance apply A negative figure means the obligation is already in force.
A29: Days to 2026-08-02 | B29: =ROUND($B$18-$B$6,0) -> -41 | C29: days | D29: ROUND(2026-08-02 - Assessed as of,0) | E29: Article 50 transparency duties apply, and AI Office enforcement over GPAI begins A negative figure means the obligation is already in force.
A30: Days to 2026-12-02 | B30: =ROUND($B$19-$B$6,0) -> 81 | C30: days | D30: ROUND(2026-12-02 - Assessed as of,0) | E30: Deadline for transparency solutions for artificially generated content A negative figure means the obligation is already in force.
A31: Days to 2027-08-02 | B31: =ROUND($B$20-$B$6,0) -> 324 | C31: days | D31: ROUND(2027-08-02 - Assessed as of,0) | E31: Member State AI regulatory sandboxes operational A negative figure means the obligation is already in force.
A32: Days to 2027-12-02 | B32: =ROUND($B$21-$B$6,0) -> 446 | C32: days | D32: ROUND(2027-12-02 - Assessed as of,0) | E32: Annex III standalone high-risk obligations apply, deferred by the Digital Omnibus A negative figure means the obligation is already in force.
A33: Days to 2028-08-02 | B33: =ROUND($B$22-$B$6,0) -> 690 | C33: days | D33: ROUND(2028-08-02 - Assessed as of,0) | E33: Annex I product-embedded high-risk obligations apply, deferred by the Digital Omnibus A negative figure means the obligation is already in force.
A34: Readiness cost | B34: =$B$11*$B$12 -> 126000 | C34: USD | D34: Readiness effort × Blended hourly cost | E34: Compliance work is engineering work, paid for out of the same budget.
A35: Days until Annex III obligations apply | B35: =$B$32 -> 446 | C35: days | D35: Days to 2027-12-02 | E35: Measured from your assessment date to 2 December 2027.
A36: Sustained effort to be ready in time | B36: =IF($B$35>0,$B$11/($B$35/$B$23),$B$11) -> 14.125561 | C36: hours per week | D36: IF(Days until Annex III obligations apply>0,Readiness effort ÷ (Days until Annex III obligations apply ÷ Days per week),Readiness effort) | E36: If this exceeds your team's slack, the deferral did not buy you what you think.

Sheet Week 11
A1: Week 11: Retrieval Corpus Retention and Cost
A2: Write the retention, lineage, and evaluation policy for a retrieval corpus that contains customer records.
A4: INPUTS YOU SUPPLY | E4: Change any figure in column B. Every computed cell below recalculates.
A5: Item | B5: Value | C5: Unit | D5: Where it comes from
A6: Documents in corpus | B6: 400000 | C6: documents | D6: Source documents before chunking.
A7: Tokens per document | B7: 1200 | C7: tokens | D7: Roughly 750 words per 1,000 tokens.
A8: Tokens per chunk | B8: 500 | C8: tokens | D8: Smaller chunks retrieve more precisely and cost more to embed and store.
A9: Chunks retrieved per answer | B9: 8 | C9: chunks | D9: Every retrieved chunk is billed as input tokens on every question.
A10: Questions per day | B10: 2000 | C10: questions | D10: Drives the generation bill, which recurs forever.
A11: Share containing personal data | B11: 35 | C11: percent | D11: Sets the perimeter for retention, deletion, and access control.
A12: Retention period | B12: 24 | C12: months | D12: How long a document stays in the corpus.
A13: Reindex interval | B13: 30 | C13: days | D13: Sets both maximum staleness and how often you pay to embed.
A14: Evaluation set size | B14: 800 | C14: documents | D14: The sample you measure retrieval quality against.
A15: Deletion request SLA | B15: 45 | C15: days | D15: What you have promised, statutorily or contractually.
A17: RATES AND CONSTANTS | E17: Published list prices link to the Rates sheet. Change a price there and every week that uses it follows.
A18: Item | B18: Value | C18: Unit | D18: Source and note
A19: Embedding dimensions | B19: 1024 | C19: dimensions | D19: Titan Text Embeddings V2 default output size.
A20: Bytes per dimension | B20: 4 | C20: bytes | D20: float32. Quantising to int8 cuts this by four with some recall loss.
A21: Output tokens per answer | B21: 400 | C21: tokens | D21: Assumed length of one generated answer.
A22: Tokens per priced block | B22: 1000000 | C22: tokens | D22: Token prices are quoted per million.
A23: Bytes per GiB | B23: 1073741824 | C23: bytes | D23: 1,024 cubed.
A24: GB per GiB | B24: 1.0737418 | C24: GB | D24: Index size is measured in GiB and storage is billed in GB.
A25: Days per year | B25: 365 | C25: days
A26: Months per year | B26: 12 | C26: months
A27: Embedding price | B27: =Rates!$C$24 -> 0.02 | C27: per 1,000,000 tokens | D27: Amazon Web Services, Bedrock Titan Text Embeddings V2, on-demand. List price retrieved 2026-08-15. Charged once per chunk at index time, and again for every chunk you reindex. Reindex frequency is an embedding bill.
A28: Generation input price | B28: =Rates!$C$25 -> 1 | C28: per 1,000,000 tokens | D28: Anthropic, Claude Haiku 4.5, input tokens. List price retrieved 2026-08-15. Retrieved chunks are input tokens. A RAG answer that stuffs 20 chunks into context pays for all 20 every time.
A29: Generation output price | B29: =Rates!$C$26 -> 5 | C29: per 1,000,000 tokens | D29: Anthropic, Claude Haiku 4.5, output tokens. List price retrieved 2026-08-15. Output costs 5x input on this model. Batch processing halves both; prompt caching cuts repeated input by roughly 90 percent.
A30: Object storage price | B30: =Rates!$C$5 -> 0.023 | C30: per GB-month | D30: Amazon Web Services, S3 Standard, first 50 TB per month, us-east-1. List price retrieved 2026-08-15. The default landing tier for a lakehouse. Billed on average bytes stored across the month, not peak.
A32: COMPUTED | E32: Each cell holds the formula shown in column D. Nothing here is typed in by hand.
A33: Figure | B33: Value | C33: Unit | D33: Equation in words | E33: Note
A34: Tokens in the corpus | B34: =$B$6*$B$7 -> 480000000 | C34: tokens | D34: Documents in corpus × Tokens per document | E34: Documents times tokens each. The quantity you pay to embed.
A35: Chunks in the index | B35: =$B$34/$B$8 -> 960000 | C35: chunks | D35: Tokens in the corpus ÷ Tokens per chunk | E35: The real unit of a retrieval corpus. Deletion, cost, and retrieval all operate on chunks.
A36: Documents containing personal data | B36: =$B$6*$B$11/100 -> 140000 | C36: documents | D36: Documents in corpus × Share containing personal data ÷ 100 | E36: Everything in scope for retention limits, deletion rights, and access control.
A37: Cost to embed the corpus once | B37: =$B$34/$B$22*$B$27 -> 9.6 | C37: USD | D37: Tokens in the corpus ÷ Tokens per priced block × Embedding price
A38: Reindex passes per year | B38: =$B$25/$B$13 -> 12.166667 | C38: passes | D38: Days per year ÷ Reindex interval | E38: How often the whole corpus is re-embedded.
A39: Embedding cost per year | B39: =$B$37*$B$38 -> 116.8 | C39: USD per year | D39: Cost to embed the corpus once × Reindex passes per year | E39: Halving the reindex interval doubles this line.
A40: Vector index size | B40: =$B$35*$B$19*$B$20/$B$23 -> 3.6621094 | C40: GiB | D40: Chunks in the index × Embedding dimensions × Bytes per dimension ÷ Bytes per GiB | E40: Vectors are often larger than the text they represent.
A41: Vector storage per year | B41: =$B$40*$B$24*$B$30*$B$26 -> 1.0852762 | C41: USD per year | D41: Vector index size × GB per GiB × Object storage price × Months per year | E41: Usually the smallest of the three bills.
A42: Input tokens per answer | B42: =$B$9*$B$8 -> 4000 | C42: tokens | D42: Chunks retrieved per answer × Tokens per chunk | E42: Every retrieved chunk is paid for on every question.
A43: Cost of one answer | B43: =$B$42/$B$22*$B$28+$B$21/$B$22*$B$29 -> 0.006 | C43: USD | D43: Input tokens per answer ÷ Tokens per priced block × Generation input price + Output tokens per answer ÷ Tokens per priced block × Generation output price | E43: Retrieved chunks as input, plus the assumed output length.
...

Sheet Week 12
A1: Week 12: Agent Access Scope and Run Cost
A2: How does an autonomous agent authenticate to your platform, what is it permitted to read, and what does that reading cost?
A4: INPUTS YOU SUPPLY | E4: Change any figure in column B. Every computed cell below recalculates.
A5: Item | B5: Value | C5: Unit | D5: Where it comes from
A6: Agent authentication method | B6: Static API key | D6: Static API key, Short-lived vended credential, or Workload identity federation.
A7: Credential lifetime | B7: 60 | C7: minutes | D7: Ignored when the method is a static key, which has no expiry.
A8: Human approval before write | B8: Not required | D8: Required or Not required.
A9: Agent queries per day | B9: 5000 | C9: queries | D9: Automated volume, typically an order of magnitude above human volume.
A10: Bytes scanned per query | B10: 0.8 | C10: GiB | D10: What one agent question actually reads off disk.
A11: Read public tables | B11: Granted | D11: Granted or Denied. Every granted row is inside the blast radius of one credential.
A12: Read internal tables | B12: Granted | D12: Granted or Denied. Every granted row is inside the blast radius of one credential.
A13: Read tables containing personal data | B13: Granted | D13: Granted or Denied. Every granted row is inside the blast radius of one credential.
A14: Write to staging | B14: Granted | D14: Granted or Denied. Every granted row is inside the blast radius of one credential.
A15: Write to production | B15: Granted | D15: Granted or Denied. Every granted row is inside the blast radius of one credential.
A17: RATES AND CONSTANTS | E17: Published list prices link to the Rates sheet. Change a price there and every week that uses it follows.
A18: Item | B18: Value | C18: Unit | D18: Source and note
A19: GB per GiB | B19: 1.0737418 | C19: GB | D19: Scan volume is measured in GiB and billed in decimal TB.
A20: GB per TB | B20: 1000 | C20: GB
A21: Days per year | B21: 365 | C21: days
A22: Volume multiple for the stress case | B22: 3 | C22: x | D22: Agents scale by configuration change, not by hiring.
A23: Scan price | B23: =Rates!$C$14 -> 5 | C23: per TB scanned | D23: Amazon Web Services, Athena, SQL over data in S3. List price retrieved 2026-08-15. You pay for bytes the engine reads, not rows returned. Compression and partitioning cut this bill directly.
A25: COMPUTED | E25: Each cell holds the formula shown in column D. Nothing here is typed in by hand.
A26: Figure | B26: Value | C26: Unit | D26: Equation in words | E26: Note
A27: Scopes granted | B27: =IF($B$11="Granted",1,0)+IF($B$12="Granted",1,0)+IF($B$13="Granted",1,0)+IF($B$14="Granted",1,0)+IF($B$15="Granted",1,0) -> 5 | C27: of 5 | D27: IF(Read public tables="Granted",1,0) + IF(Read internal tables="Granted",1,0) + IF(Read tables containing personal data="Granted",1,0) + IF(Write to staging="Granted",1,0) + IF(Write to production="Granted",1,0) | E27: Count of what one compromised credential reaches.
A28: Credential exposure window | B28: =IF($B$6="Static API key","Unbounded",$B$7) -> Unbounded | C28: minutes | D28: IF(Agent authentication method="Static API key","Unbounded",Credential lifetime) | E28: How long a stolen credential stays valid with nobody intervening. A static key never expires.
A29: Cost of one agent query | B29: =$B$10*$B$19/$B$20*$B$23 -> 0.0042949673 | C29: USD | D29: Bytes scanned per query × GB per GiB ÷ GB per TB × Scan price | E29: An agent pays the same per-TB price a human does.
A30: Cost of one agent, per day | B30: =$B$29*$B$9 -> 21.474836 | C30: USD per day | D30: Cost of one agent query × Agent queries per day | E30: The daily run rate of an identity that never sleeps.
A31: Agent read spend per year | B31: =$B$30*$B$21 -> 7838.3153 | C31: USD per year | D31: Cost of one agent, per day × Days per year | E31: Nobody complains about this bill because nobody is waiting on the result.
A32: Spend if query volume triples | B32: =$B$31*$B$22 -> 23514.946 | C32: USD per year | D32: Agent read spend per year × Volume multiple for the stress case | E32: Budget for the configuration change.

Sheet Rates
A1: Published list prices
A2: Every figure is a US-region, on-demand, list price with no negotiated discount applied. Change a price here and every week sheet that uses it recalculates. You are still required to retrieve and date your own prices.
A4: Key | B4: Vendor | C4: Unit price, USD | D4: Unit | E4: Retrieved | F4: Source | G4: Note
A5: objectStorageStandard | B5: Amazon Web Services, S3 Standard, first 50 TB per month, us-east-1 | C5: 0.023 | D5: per GB-month | E5: 2026-08-15 | F5: https://aws.amazon.com/s3/pricing/ | G5: The default landing tier for a lakehouse. Billed on average bytes stored across the month, not peak.
A6: objectStorageInfrequent | B6: Amazon Web Services, S3 Standard-Infrequent Access, us-east-1 | C6: 0.0125 | D6: per GB-month | E6: 2026-08-15 | F6: https://aws.amazon.com/s3/pricing/ | G6: Roughly half the storage rate, but retrieval is charged per GB read. Cheap only if you rarely read it.
A7: objectStorageArchive | B7: Amazon Web Services, S3 Glacier Instant Retrieval, us-east-1 | C7: 0.004 | D7: per GB-month | E7: 2026-08-15 | F7: https://aws.amazon.com/s3/pricing/ | G7: About one sixth of Standard, with a 90-day minimum storage duration and a per-GB retrieval charge.
A8: objectStorageDeepArchive | B8: Amazon Web Services, S3 Glacier Deep Archive, us-east-1 | C8: 0.00099 | D8: per GB-month | E8: 2026-08-15 | F8: https://aws.amazon.com/s3/pricing/ | G8: Around 4 percent of Standard, with a 180-day minimum and retrieval measured in hours, not milliseconds.
A9: warehouseStorage | B9: Snowflake, On-demand storage, US East | C9: 23 | D9: per TB-month | E9: 2026-08-15 | F9: https://www.snowflake.com/en/data-cloud/pricing-options/ | G9: Warehouse-managed storage. Compare against $23.55 per TB-month for the same bytes on S3 Standard.
A10: putRequests | B10: Amazon Web Services, S3 PUT, COPY, POST, LIST requests, us-east-1 | C10: 0.005 | D10: per 1,000 requests | E10: 2026-08-15 | F10: https://aws.amazon.com/s3/pricing/ | G10: The reason small files are expensive. A million 1 MB files cost 200x the request charge of a thousand 1 GB files.
A11: getRequests | B11: Amazon Web Services, S3 GET and SELECT requests, us-east-1 | C11: 0.0004 | D11: per 1,000 requests | E11: 2026-08-15 | F11: https://aws.amazon.com/s3/pricing/ | G11: Each file a query opens is at least one GET. File layout is therefore a cost decision, not only a speed one.
A12: computeSingleNode | B12: Amazon Web Services, EC2 r5.16xlarge on-demand, 64 vCPU and 512 GiB RAM, us-east-1, Linux | C12: 4.032 | D12: per node-hour | E12: 2026-08-15 | F12: https://aws.amazon.com/ec2/pricing/on-demand/ | G12: The single-node ceiling used throughout Week 1. 512 GiB of RAM in one machine, one address space, no network hop.
A13: computeWorkerNode | B13: Amazon Web Services, EC2 r5.4xlarge on-demand, 16 vCPU and 128 GiB RAM, us-east-1, Linux | C13: 1.008 | D13: per node-hour | E13: 2026-08-15 | F13: https://aws.amazon.com/ec2/pricing/on-demand/ | G13: One worker in a distributed cluster. Exactly one quarter the RAM and one quarter the price of the single node above.
A14: scanPerTb | B14: Amazon Web Services, Athena, SQL over data in S3 | C14: 5 | D14: per TB scanned | E14: 2026-08-15 | F14: https://aws.amazon.com/athena/pricing/ | G14: You pay for bytes the engine reads, not rows returned. Compression and partitioning cut this bill directly.
A15: scanPerTib | B15: Google Cloud, BigQuery on-demand analysis, first 1 TiB per month free | C15: 6.25 | D15: per TiB scanned | E15: 2026-08-15 | F15: https://cloud.google.com/bigquery/pricing | G15: Priced per TiB (1,024^4 bytes), not per TB (1,000^4). The two differ by about 10 percent, which matters at scale.
A16: slotHour | B16: Google Cloud, BigQuery Standard edition capacity | C16: 0.04 | D16: per slot-hour | E16: 2026-08-15 | F16: https://cloud.google.com/bigquery/pricing | G16: Capacity pricing. You rent parallelism by the hour instead of paying per byte scanned.
... A26: generationOutputTokens | B26: Anthropic, Claude Haiku 4.5, output tokens | C26: 5 | D26: per 1,000,000 tokens | E26: 2026-08-15 | F26: https://claude.com/pricing | G26: Output costs 5x input on this model. Batch processing halves both; prompt caching cuts repeated input by roughly 90 percent.
